export const withErrorBoundary = (fn, fallback = null) => {
  try {
    return fn();
  } catch (error) {
    console.error('Error caught:', error);
    return fallback;
  }
};

export const retryOperation = async (operation, maxRetries = 3, delay = 1000) => {
  for (let i = 0; i < maxRetries; i++) {
    try {
      return await operation();
    } catch (error) {
      if (i === maxRetries - 1) throw error;
      await new Promise(resolve => setTimeout(resolve, delay * (i + 1)));
    }
  }
};

export const debounce = (func, wait) => {
  let timeout;
  return function executedFunction(...args) {
    const later = () => {
      clearTimeout(timeout);
      func(...args);
    };
    clearTimeout(timeout);
    timeout = setTimeout(later, wait);
  };
};